## Exception safety guarantee

- ### throw exception을 사용하는 경우 `Exception safety`를 지켜야 한다. 그렇지 않으면 `memory leak / resource leak`이 발생할 수 있다.

  - #### memory leak은 Heap 영역에서 할당된 자원이 정상적으로 반환되지 않아 계속 차지하고 있는 경우를 말한다.
  - #### resoruce leak은 외부 자원, 즉 데이터베이스, 파일등 외부 자원에 대한 접근이 반환되지 않는 경우를 말한다.

- ### exception safety는 4종류가 있다.

  - #### no exception safety: memory / resource leak이 생기는 경우. smart_ptr을 사용함으로 써 RAII idiom을 지키고, memory leak을 방지할 수 있다.
  - #### basic exception safety: 해당 method에서 참조하는 변수의 state가 변경 가능성이 있는 경우, 변경 되는 경우

  ```cpp
  int divide(int a, int b) {
  if (b == 0) {
  	throw std::runtime_error("divide by 0");
  } else
  	return a / b;
  }
  void fn(int a, int b, int& c) {
    // c의 state가 변경된 후 exception handling이 발생해도, c의 변경된 값이 그대로 유지 된다.
    // 이러한 경우를 basic exception safety 라고 한다.
    c++;
    try {
      divide(a, b);
    } catch (std::exception e) {
      cout << e.what();
    }
  }

  int main() {
    int a = 3;
    fn(1, 0, a);
    cout << a;
    return 0;
  }
  ```

  - #### strong exception safety: exception발생시, 변수의 state가 변하지 않는 경우.

    - #### 이러한 경우는 try-catch문 이후의 변수의 상태값을 변경하는 처리를 하면 strong exception safety를 준수하게 된다.

  - #### no-throw guarantee: exception이 해당 call stack까지 `propagation`되지 않아 exception handling이 발생하지 않는 경우

    ```cpp
    int divide(int a, int b) {
    if (b == 0) {
    	throw std::runtime_error("divide by 0");
    } else
    	return a / b;
    }
    void fn(int a, int b, int& c) { // exception handling을 하고 있는 fn은 no-throw guarantee를 준수하지 않음.
    c++;
    try {
      divide(a, b);
       } catch (std::exception e) {
        cout << e.what();
      }
    }

    int main() {
    int a = 3;
    fn(1, 0, a); // fn을 호출하는 main 함수는 no-throw guarantee를 준수함. 왜냐하면 exception이 main까지 propagation되지 않고, fn까지만 propagation되어 handling되기 때문.
    cout << a;
    return 0;
    }

    ```
