## Exception - 예외처리

### - C++에서는 `try - catch - throw`를 통한 `exception` / 예외처리가 가능하다.

### - C언어는 error가 발생하면 return 으로 특수 값을 주거나 함으로써 예외처리 한다.

### - C++에서는 error상황이 오면 `enum class`와 `tuple, pair, variant`등 다중 값을 포함할 수 있는 template를 이용해서 예외처리를 하거나 `try - catch - throw`문으로 예외처리를 할 수 있다.

### - throw문으로 `class instance / object`를 던질 수 있다.

### - throw를 통해 생성된 `exception object`는 일반적이로 `heap`영역에 저장이 된다 하지만 이는 `compiler 구현`에 따라 다르다. c++ standard에서는 정확이 어디에 할당이 되는지 정의되어 있지 않다고 한다.

### - exception object가 주어지면 `stack unwinding`을 통해 stack frame이 역순으로 반환 된다. 반환된 stack frame 안에 할당된 동적인 지역 변수등도 메모리상에서 안전하게 반환된다. exception object는 적절한 catch문을 찾아 가는 과정을 거친다.

### - 적절한 catch문을 찾아간 exception object는 해당 catch문에 정의된 exception object reference에 바인딩이 되고, catch문에서 처리 될 수 있다.

### - throw로 주는 error object는 `R value`로 주어져야 하고 이를 catch문에서 참조하는 argument는 `reference`로 참조 해야 한다.

```cpp

int divide(int a, int b) {
	if (b == 0)
		throw std::runtime_error("divide 0!"); // runtime_error를 생성하고 throw
	return a / b;
}

int main() {
	int w;
	try {
		w = divide(1, 0);

	} catch (std::exception& e) { // std::runtime_error class는 exception class의 derived class이므로 참조 가능.
		cout << e.what(); // what()으로 message 출력
		w = 0;
	}

	cout << w;
	return 0;
}

```

- ### throw문으로 다른 타입의 객체도 생성해서 던질 수 있다. 하지만 이는 try - catch문을 사용하는 목적에 어긋나기 때문에 권장하지 않는다.

```cpp
  class Cat {
public:
	Cat(std::string msg) : message{std::move(msg)} {}
	void speak() { cout << message; };

private:
	std::string message;
};

int divide(int a, int b) {
	if (b == 0)
		throw Cat("ghfltlt");
	return a / b;
}

int main() {
	int w;
	try {
		w = divide(1, 0);
	} catch (std::exception& e) {
		std::cout << e.what();
		w = 0;
	} catch (Cat& c) { // 여러 catch문을 줄 수 있다. 여러 종류의 exception handling이 가능하다.
		c.speak(); // ghfltlt 출력
	}

	return 0;
}

```
